<?xml version="1.0"?>
<robot name="my_robot2">
    <material name="grey">
        <color rgba="0.7 0.7 0.7 1.0"/>
    </material>
    <material name="blue">
        <color rgba="0.0 0.5 1.0 1.0"/>
    </material>
    <material name="green">
        <color rgba="0.0 0.6 0.0 1.0"/>
    </material>
    <material name="white">
        <color rgba="1.0 1.0 1.0 1.0"/>
    </material>

    <link name ="base_link">
        <visual>
            <geometry>
                <box size="0.6 0.4 0.2"/>
            </geometry>
            <origin xyz="0.0 0.0 0.1" rpy="0.0 0.0 0.0"/>
            <material name="blue"/>
        </visual>
    </link>
    
    <link name="second_link">
        <visual>
            <geometry>
                <cylinder radius="0.1" length="0.2"/>
            </geometry>
            <origin xyz="0.0 0.0 0.1" rpy="0.0 0.0 0.0"/>
            <material name="grey"/>
        </visual>
    </link>

    <!-- <link name="third_link">
        <visual>
            <geometry>
                <box size="0.1 0.1 0.1"/>
            </geometry>
            <origin xyz="0.0 0.0 0.05" rpy="0.0 0.0 0.0"/>
            <material name="grey"/>
        </visual>
    </link> -->

    <joint name="base_second_joint" type="prismatic">
        <parent link="base_link"/>
        <child link="second_link"/>
        <origin xyz="0.0 0.0 0.2" rpy="0.0 0.0 0.0"/>
        <axis xyz="1.0 0.0 0.0"/>
        <limit lower="0" upper="0.2" effort="100.0" velocity="100.0"/>
    </joint>

    <!-- <joint name="second_third_joint" type="fixed">
        <parent link="second_link"/>
        <child link="third_link"/>
        <origin xyz="0.0 0.0 0.2" rpy="0.0 0.0 0.0"/>
    </joint> -->

</robot>